Workbook

Sheet Frente - Relatório de SC - 1
AS1: RSC
K2: KTSA Automação Industrial LTDA.
A4: RELATÓRIO DE SERVIÇOS DE CAMPO
A5: Empresa: | AE5: Número CPM:
A6: Endereço: | G6: =IF(G5="","",VLOOKUP(G5,'KM e Tempo Percurso'!A7:O201,4,0))
A7: Bairro: | G7: =IF(G5="","",VLOOKUP(G5,'KM e Tempo Percurso'!A7:O201,5,0)) | V7: Cidade: | Z7: =IF(G5="","",VLOOKUP(G5,'KM e Tempo Percurso'!A7:O201,2,0)) | AR7: Estado: | AV7: =IF(G5="","",VLOOKUP(G5,'KM e Tempo Percurso'!A7:O201,3,0))
A8: Solicitante: | G8: =IF(G5="","",VLOOKUP(G5,'KM e Tempo Percurso'!A7:O201,6,0)) | AE8: Departamento: | AL8: =IF(G5="","",VLOOKUP(G5,'KM e Tempo Percurso'!A7:O201,7,0))
A9: E-mail: | G9: =IF(G5="","",VLOOKUP(G5,'KM e Tempo Percurso'!A7:O201,8,0)) | AE9: Telefone / Fax: | AL9: =IF(G5="","",VLOOKUP(G5,'KM e Tempo Percurso'!A7:O201,9,0))
A10: Serviço: | F10: Levantamento de Campo | U10: Comissionamento | AH10: Start-up | AQ10: Operação Assistida
F11: Assistência Técnica | U11: Contrato de Manutenção | AH11: Outro | AQ11: Periculosidade
A12: Serviços a executar:
A13: Área:
A16: RELATÓRIO DE HORAS
A17: DIA DA SEMANA | M17: SEG | R17: TER | W17: QUA | AB17: QUI | AG17: SEX | AL17: SAB | AQ17: DOM | AV17: SEG
A18: DATA (Dia/Mês/Ano)
A19: Horário de Chegada
A20: Horário de Saída
A21: Intervalo (Almoço/Jantar)
A22: Deslocamento Ida | M22: =IF(G5="","",VLOOKUP(G5,'KM e Tempo Percurso'!A7:O201,13,0)) | R22: =IF(G5="","",VLOOKUP(G5,'KM e Tempo Percurso'!A7:O201,13,0)) | W22: =IF(G5="","",VLOOKUP(G5,'KM e Tempo Percurso'!A7:O201,13,0)) | AB22: =IF(G5="","",VLOOKUP(G5,'KM e Tempo Percurso'!A7:O201,13,0)) | AG22: =IF(G5="","",VLOOKUP(G5,'KM e Tempo Percurso'!A7:O201,13,0)) | AL22: =IF(G5="","",VLOOKUP(G5,'KM e Tempo Percurso'!A7:O201,13,0)) | AQ22: =IF(G5="","",VLOOKUP(G5,'KM e Tempo Percurso'!A7:O201,13,0)) | AV22: =IF(G5="","",VLOOKUP(G5,'KM e Tempo Percurso'!A7:O201,13,0))
A23: Deslocamento Volta | M23: =IF(G5="","",VLOOKUP(G5,'KM e Tempo Percurso'!A7:O201,14,0)) | R23: =IF(G5="","",VLOOKUP(G5,'KM e Tempo Percurso'!A7:O201,14,0)) | W23: =IF(G5="","",VLOOKUP(G5,'KM e Tempo Percurso'!A7:O201,14,0)) | AB23: =IF(G5="","",VLOOKUP(G5,'KM e Tempo Percurso'!A7:O201,14,0)) | AG23: =IF(G5="","",VLOOKUP(G5,'KM e Tempo Percurso'!A7:O201,14,0)) | AL23: =IF(G5="","",VLOOKUP(G5,'KM e Tempo Percurso'!A7:O201,14,0)) | AQ23: =IF(G5="","",VLOOKUP(G5,'KM e Tempo Percurso'!A7:O201,14,0)) | AV23: =IF(G5="","",VLOOKUP(G5,'KM e Tempo Percurso'!A7:O201,14,0))
A24: Distância Ida (Km) | M24: =IF(G5="","",VLOOKUP(G5,'KM e Tempo Percurso'!A7:O201,10,0)) | R24: =IF(G5="","",VLOOKUP(G5,'KM e Tempo Percurso'!A7:O201,10,0)) | W24: =IF(G5="","",VLOOKUP(G5,'KM e Tempo Percurso'!A7:O201,10,0)) | AB24: =IF(G5="","",VLOOKUP(G5,'KM e Tempo Percurso'!A7:O201,10,0)) | AG24: =IF(G5="","",VLOOKUP(G5,'KM e Tempo Percurso'!A7:O201,10,0)) | AL24: =IF(G5="","",VLOOKUP(G5,'KM e Tempo Percurso'!A7:O201,10,0)) | AQ24: =IF(G5="","",VLOOKUP(G5,'KM e Tempo Percurso'!A7:O201,10,0)) | AV24: =IF(G5="","",VLOOKUP(G5,'KM e Tempo Percurso'!A7:O201,10,0))
A25: Distância volta (Km) | M25: =IF(G5="","",VLOOKUP(G5,'KM e Tempo Percurso'!A7:O201,11,0)) | R25: =IF(G5="","",VLOOKUP(G5,'KM e Tempo Percurso'!A7:O201,11,0)) | W25: =IF(G5="","",VLOOKUP(G5,'KM e Tempo Percurso'!A7:O201,11,0)) | AB25: =IF(G5="","",VLOOKUP(G5,'KM e Tempo Percurso'!A7:O201,11,0)) | AG25: =IF(G5="","",VLOOKUP(G5,'KM e Tempo Percurso'!A7:O201,11,0)) | AL25: =IF(G5="","",VLOOKUP(G5,'KM e Tempo Percurso'!A7:O201,11,0)) | AQ25: =IF(G5="","",VLOOKUP(G5,'KM e Tempo Percurso'!A7:O201,11,0)) | AV25: =IF(G5="","",VLOOKUP(G5,'KM e Tempo Percurso'!A7:O201,11,0))
A27: DESPESAS
A28: Descrição | T28: R$ | AA28: Descrição | AT28: R$
A29: Pedágio | AA29: Refeição
A30: Passagem | AA30: Hotel
A31: Outros (Especificar) | AA31: Outros (Especificar)
A33: Desenvolvimento no cliente dentro do escopo. Horas não debitadas do contrato | S33: Horas dentro do escopo. Start-up/Acompanhamento | AH33: Serviço caracterizado como alteração de Escopo. Serviço H/H
A35: 5.0-Desenvolvimento Software PLC | S35: 6.0-Deslocamento/Viagem | AH35: 8.0-Assist Técnica
A36: 5.1-Desenvolvimento Software Supervisório | S36: 6.1-Exames/Integração | AH36: 8.1-Suporte Técnico
A37: 5.2-Desenvolvimento Software IHM | S37: 6.2-Comissionamento | AH37: 8.2-Serviço Adicional
A38: 5.3-Desenvolvimento Software Redes Comun. | S38: 6.3-Teste Funcional/Start-up | AH38: 9.0-Serviço de Montagem
A39: 5.4-Inspeção e Teste | S39: 6.4-Operação Assistida
A40: 5.5-Teste Aceitação Fabrica | S40: 6.5-Treinamento Operação/Manut.
S41: 7.0-Garantia
S42: 7.1-Contrato Manutenção
A44: Horas trabalhadas "Fora do Horário Normal de Trabalho", Sábados, Domingos e Feriados serão cobradas adicionalmente como horas extras conforme nossa proposta comercial. Horas paradas por responsabilidade do cliente serão cobradas conforme valores vigentes quando do Serviço de Campo.
A48: Ass. Cliente / Data | S48: Ass. Técnico / Data | AK48: Responsável KTSA / Data
A49: Nome: | S49: Nome: | AK49: RSC_rev.38
D53: ALAN FERREIRA
...

Sheet Verso - Relatório de SC - 2
AS1: RSC
K2: KTSA Automação Industrial LTDA.
A4: RELATÓRIO DE SERVIÇOS DE CAMPO
A5: Código | E5: Descrição dos Serviços Executados:
A46: Ass. Cliente / Data | S46: Ass. Técnico / Data | AK46: Responsável KTSA / Data
AK47: RSC_rev.38

Sheet KM e Tempo Percurso
A1: #VALUE!
A4: RELATÓRIO DE SERVIÇOS DE CAMPO
A5: Destino | B5: Cidade | C5: Estado | D5: Endereço | E5: Bairro | F5: Solicitante | G5: Area | H5: e-mail | I5: Telefone | J5: Distância do percurso (Km) da KTSA até o cliente | M5: Tempo do percurso (Horas) da KTSA até o cliente
J6: Ida | K6: Volta | L6: Total | M6: Ida | N6: Volta | O6: Total
A7: ABB (Guarulhos) | B7: Guarulhos | C7: SP | D7: Av. Monteiro Lobato, 3411 | E7: Vila São Roque | I7: (11) 2464-8188 | J7: 55 | K7: 55 | L7: =J7+K7 -> 110 | M7: 0.041666667 | N7: 0.041666667 | O7: =M7+N7 -> 0.083333333
A8: ABB (Osasco) | B8: Osasco | C8: SP | D8: Av. dos Autonomistas, 1496 | E8: Industrial Autonomistas | F8: - | G8: - | H8: - | I8: (11) 3688-9111 | J8: 70 | K8: 70 | L8: =J8+K8 -> 140 | M8: 0.041666667 | N8: 0.041666667 | O8: =M8+N8 -> 0.083333333
A9: Acrilex | B9: São Bernardo do Campo | C9: SP | D9: Est Galvao Bueno, 5000 | E9: Batistine | F9: - | G9: - | H9: - | I9: - | J9: 15 | K9: 15 | L9: =J9+K9 -> 30 | M9: 0.020833333 | N9: 0.020833333 | O9: =M9+N9 -> 0.041666667
A10: Anglo American | B10: Cubatão | C10: SP | D10: Rod. Dom Domênico Rangoni km 264,2 | E10: Vila Elizabeth | F10: - | G10: - | H10: - | I10: (13) 3372-5255 | J10: 45 | K10: 45 | L10: =J10+K10 -> 90 | M10: 0.041666667 | N10: 0.041666667 | O10: =M10+N10 -> 0.083333333
A11: Arvin Meritor | B11: Osasco | C11: SP | D11: Av. João Batista, 825 | E11: Centro | F11: - | G11: - | H11: - | I11: (11) 3699-4375 | J11: 75 | K11: 75 | L11: =J11+K11 -> 150 | M11: 0.041666667 | N11: 0.041666667 | O11: =M11+N11 -> 0.083333333
A12: Avon | B12: São Paulo | C12: SP | D12: Av. Interlagos, 4300 | E12: Interlagos | F12: - | G12: - | H12: - | I12: (11) 5546-6135 | J12: 30 | K12: 30 | L12: =J12+K12 -> 60 | M12: 0.041666667 | N12: 0.041666667 | O12: =M12+N12 -> 0.083333333
A13: Akzo Nobel | B13: Mauá | C13: SP | D13: Av. Papa João XXIII, 2100 | E13: Lot. Industrial Coral | F13: - | G13: - | H13: - | I13: - | J13: 25 | K13: 25 | L13: =J13+K13 -> 50 | M13: 0.020833333 | N13: 0.020833333 | O13: =M13+N13 -> 0.041666667
A14: Bauducco | B14: Guarulhos | C14: SP | D14: R. Carlo Bauduco, 200 | E14: Vila Paraiso | F14: Anderson Silva | G14: Eng. de Automação | H14: asilva.br@inoxpa.com | I14: (11) 97443-8615 | J14: 70 | K14: 70 | L14: =J14+K14 -> 140 | M14: 0.041666667 | N14: 0.041666667 | O14: =M14+N14 -> 0.083333333
A15: Basf | B15: São Bernardo do Campo | C15: SP | D15: Av. Ângelo Demarchi, 123 | E15: Demarchi | F15: Rodrigo Vitale | G15: Engenharia | H15: rodrigo.vitale@basf.com | I15: (11) 4358-7635 | J15: 15 | K15: 15 | L15: =J15+K15 -> 30 | M15: 0.020833333 | N15: 0.020833333 | O15: =M15+N15 -> 0.041666667
A16: Baxter Hospitalar | B16: São Paulo | C16: SP | D16: Av. Eng. Eusébio Stevaux, 2555 | E16: Jurubatuba | F16: - | G16: Eng. de Automação | H16: - | I16: - | J16: 35 | K16: 35 | L16: =J16+K16 -> 70 | M16: 0.041666667 | N16: 0.041666667 | O16: =M16+N16 -> 0.083333333
A17: Baxter | B17: São Paulo | C17: SP | D17: Av. Eng. Eusébio Stevaux, 2555 | E17: Jurubatuba | F17: Paulo Cunha | G17: Eng. de Manutenção | H17: paulo_cunha@baxter.com | I17: (11) 98542-2645 | J17: 35 | K17: 35 | L17: =J17+K17 -> 70 | M17: 0.041666667 | N17: 0.041666667 | O17: =M17+N17 -> 0.083333333
A18: Bayer (Vila Socorro) | B18: São Paulo | C18: SP | D18: Rua Alexandre Gusmão, s/n | E18: Vila Socorro | F18: Lino Teruo | G18: Eng. de Manutenção | H18: lino.teruo@bayer.com | I18: (11) 97969-1569 | J18: 45 | K18: 45 | L18: =J18+K18 -> 90 | M18: 0.041666667 | N18: 0.041666667 | O18: =M18+N18 -> 0.083333333
A19: Braskem (PE7) | B19: Santo André | C19: SP | D19: Av. Presidente Costa e Silva, 400 | E19: Parque Capuava | F19: José Ensinas Júnior | G19: Eng. de Automação | H19: jose.ensinas@braskem.com | I19: (11) 4478-4064 | J19: 30 | K19: 30 | L19: =J19+K19 -> 60 | M19: 0.020833333 | N19: 0.020833333 | O19: =M19+N19 -> 0.041666667
... A45: Eirich | B45: Jandira | C45: SP | D45: Estrada Velha de Itu, 1500 | E45: Jardim Alvorada | F45: Fábio Nunes | G45: Engenharia Elétrica | H45: fabio.nunes@eirich.com.br | I45: (11) 4619-8914 | J45: 85 | K45: 85 | L45: =J45+K45 -> 170 | M45: 0.041666667 | N45: 0.041666667 | O45: =M45+N45 -> 0.083333333
A46: Eurofarma | B46: Itapevi | C46: SP | D46: Rod. Pres. Castello Branco, 3565 | E46: Itaqui | F46: Guilherme Chida | G46: - | H46: - | J46: 85 | K46: 85 | L46: =J46+K46 -> 170 | M46: 0.0625 | N46: 0.0625 | O46: =M46+N46 -> 0.125
A47: Gelita do Brasil | B47: Cotia | C47: SP | D47: Rua Philip Leiner, 200 | E47: Parque Alexandre | F47: Victor Ramon | G47: Engenharia | H47: victor.ramon@gelita.com | I47: (44) 99111-7101 | J47: 70 | K47: 70 | L47: =J47+K47 -> 140 | M47: 0.041666667 | N47: 0.041666667 | O47: =M47+N47 -> 0.083333333
A48: Gelita do Brasil | B48: Maringá | C48: PR | D48: Rod Pr-317 (Saida Para Iguaracu), Km 85 | E48: Parque Industrial 200 | F48: Kleber Martins | G48: Engenharia | H48: kleber.martins@gelita.com | I48: (44) 4009-5589 | J48: 700 | K48: 700 | L48: =J48+K48 -> 1400 | M48: 0.375 | N48: 0.375 | O48: =M48+N48 -> 0.75
A49: Gelita do Brasil | B49: Mococa | C49: SP | D49: Av. Tiradentes, s/n | E49: Jardim Santa Cecilia | F49: Lucas Mizota | G49: Engenharia | H49: lucas.mizota@gelita.com | I49: (44) 4009-5603 | J49: 320 | K49: 320 | L49: =J49+K49 -> 640 | M49: 0.16666667 | N49: 0.16666667 | O49: =M49+N49 -> 0.33333333
A50: Gerdau | B50: Divinopolis | C50: MG | D50: Av. Gabriel Passos,102 | E50: Porto Velho | I50: (37) 3229-1500 | J50: 540 | K50: 540 | L50: =J50+K50 -> 1080 | M50: 0.29166667 | N50: 0.29166667 | O50: =M50+N50 -> 0.58333333
A51: GM Mogi | B51: Mogi das Cruzes | C51: SP | D51: Av General Motors, 1999 | E51: Taboao | F51: Marcelo Gianetti de Jesus | G51: Engenharia | H51: marcelo.dejesus@gm.com | I51: (11) 4239-6285 | J51: 70 | K51: 70 | L51: =J51+K51 -> 140 | M51: 0.041666667 | N51: 0.041666667 | O51: =M51+N51 -> 0.083333333
A52: GM Polimeros | B52: São Caetano do Sul | C52: SP | D52: Av Prosperidade, 774 | E52: Prosperidade | F52: Jonathan Muñoz Segura | G52: Engenharia | H52: jonathan.munoz@gm.com | I52: (11) 4239-2285 | J52: 30 | K52: 30 | L52: =J52+K52 -> 60 | M52: 0.03125 | N52: 0.03125 | O52: =M52+N52 -> 0.0625
A53: GM São Caetano | B53: São Caetano do Sul | C53: SP | D53: Av Goias | E53: Santo Antônio | F53: - | G53: - | H53: - | I53: - | J53: 25 | K53: 25 | L53: =J53+K53 -> 50 | M53: 0.020833333 | N53: 0.020833333 | O53: =M53+N53 -> 0.041666667
A54: GM São José | B54: São José dos Campos | C54: SP | D54: Av. General Motors, 1959 | E54: Jardim Motorama | F54: - | G54: - | H54: - | I54: - | J54: 120 | K54: 120 | L54: =J54+K54 -> 240 | M54: 0.0625 | N54: 0.0625 | O54: =M54+N54 -> 0.125
A55: Hydraforce | B55: Taboão da Serra | C55: SP | D55: Av. Laurita Ortega Mari, 499 | E55: Parque Industrial das Oliveiras | F55: - | J55: 60 | K55: 60 | L55: =J55+K55 -> 120 | M55: 0.041666667 | N55: 0.041666667 | O55: =M55+N55 -> 0.083333333
A56: Houghton | B56: Mauá | C56: SP | D56: Rua Alpont, 394 | E56: Capuava | F56: - | G56: - | H56: - | I56: - | J56: 30 | K56: 30 | L56: =J56+K56 -> 60 | M56: 0.020833333 | N56: 0.020833333 | O56: =M56+N56 -> 0.041666667
A57: Houghton RJ | B57: Campo Grande | C57: RJ | D57: Avenida Brasil, 44178 | E57: Campo Grande | J57: 420 | K57: 420 | L57: =J57+K57 -> 840 | M57: 0.25 | N57: 0.25 | O57: =M57+N57 -> 0.5
A58: ICE Cartões Especiais | B58: São Paulo | C58: SP | D58: Av. Jorn Paulo Zingg, 560 | E58: Jardim Jaraguá | F58: - | G58: - | H58: - | I58: (11) 3904-8102 | J58: 80 | K58: 80 | L58: =J58+K58 -> 160 | M58: 0.041666667 | N58: 0.041666667 | O58: =M58+N58 -> 0.083333333
A59: Inoxpa | B59: São Bernardo do Campo | C59: SP | D59: R. Tita Coelho,44 | E59: Bairro Assunção | F59: Anderson Silva | G59: Engenharia | H59: asilva.br@inoxpa.com | I59: (11) 97443-8615 | J59: 15 | K59: 15 | L59: =J59+K59 -> 30 | M59: 0.010416667 | N59: 0.010416667 | O59: =M59+N59 -> 0.020833333
A60: Invicta | B60: Pouso Alegre | C60: MG | D60: Al Manoel Antonio Sobral, 701 | E60: Distrito Industrial | F60: Antonio Marcos de Moura | G60: Supervisor de Manutenção | H60: antonio.silva@coleman.com | I60: (35) 99191-6334 | J60: 225 | K60: 225 | L60: =J60+K60 -> 450 | M60: 0.14583333 | N60: 0.14583333 | O60: =M60+N60 -> 0.29166667
A61: Libbs | B61: Embu das Artes | C61: SP | D61: ua Alberto Correia Francfort, 88 | E61: Jardim Vista Alegre | J61: 60 | K61: 60 | L61: =J61+K61 -> 120 | M61: 0.041666667 | N61: 0.041666667 | O61: =M61+N61 -> 0.083333333
A62: Louis Dreyfus Company | B62: Matão | C62: SP | D62: Estrada da Fazenda, 6000 | E62: Boa Vista | F62: Marcos Rolon | G62: Engenharia | H62: marcos@attc.com.br | I62: (11) 97214-0988 | J62: 360 | K62: 360 | L62: =J62+K62 -> 720 | M62: 0.20833333 | N62: 0.20833333 | O62: =M62+N62 -> 0.41666667
A63: Lubrizol (Regren) | B63: Paulinia | C63: SP | D63: Rua Sebastião Cardoso, 574 | E63: Okinawa | F63: Reginaldo Sipan | G63: Engenharia | H63: reginaldo.sipan@regren.com.br | I63: (11) 98776-8614 | J63: 175 | K63: 175 | L63: =J63+K63 -> 350 | M63: 0.083333333 | N63: 0.083333333 | O63: =M63+N63 -> 0.16666667
A64: Mac Jee | B64: Paraíbuna | C64: SP | D64: - | E64: Paraíbuna | F64: - | G64: - | H64: - | I64: - | J64: 150 | K64: 150 | L64: =J64+K64 -> 300 | M64: 0.072916667 | N64: 0.072916667 | O64: =M64+N64 -> 0.14583333
A65: M&G | B65: Poços de Calda | C65: MG | D65: Av. Celanese, 3000 | E65: Bortolan | F65: - | G65: - | H65: - | I65: (35) 3714-1124 | J65: 285 | K65: 285 | L65: =J65+K65 -> 570 | M65: 0.16666667 | N65: 0.16666667 | O65: =M65+N65 -> 0.33333333
A66: Mercedes-Benz MG | B66: Juíz de Fora | C66: MG | D66: Rod. Pres. Juscelino Kubitschek | E66: Juiz de Fora | F66: - | G66: - | H66: - | I66: - | J66: 550 | K66: 550 | L66: =J66+K66 -> 1100 | M66: 0.3125 | N66: 0.3125 | O66: =M66+N66 -> 0.625
A67: Mercedes-Benz | B67: São Bernardo do Campo | C67: SP | D67: Rua Alfred Jurzykowski 562 | E67: Pauliceia | F67: Luiz Marcelo | G67: Engenharia | H67: luiz.marcelo@daimler.com | I67: (11) 4173-7961 | J67: 20 | K67: 20 | L67: =J67+K67 -> 40 | M67: 0.020833333 | N67: 0.020833333 | O67: =M67+N67 -> 0.041666667
...

Sheet KM Hotel
A1: #VALUE!
A4: KM HOTÉIS
A5: Origem | B5: Hotel Destino | C5: Cidade | D5: Estado | E5: Endereço | F5: Bairro | G5: Telefone | H5: Distância do percurso (Km) da KTSA até o cliente | K5: Tempo do percurso (Horas) da KTSA até o cliente
H6: Ida | I6: Volta | J6: Total | K6: Ida | L6: Volta | M6: Total
A7: Braskem (PP3) | B7: Metropole Paulinia | C7: Paulínia | D7: SP | E7: Av. Aristóteles Costa, 490 | F7: Jardim Fortaleza | G7: (19) 3933-2752 | H7: 10 | I7: 10 | J7: =H7+I7 -> 20 | K7: 0.010416667 | L7: 0.0069444444 | M7: =K7+L7 -> 0.017361111
A8: Braskem (PP3) | B8: Bonno Hotel | C8: Paulínia | D8: SP | E8: Rua Sebastião Cardoso, 574 | F8: Parque Brasil | G8: (19) 3888-2545 | H8: 15 | I8: 15 | J8: =H8+I8 -> 30 | K8: 0.010416667 | L8: 0.010416667 | M8: =K8+L8 -> 0.020833333
A9: Cargill | B9: São Roque Park Hotel | C9: Mairinque | D9: SP | E9: Av. Antônino Dias Bastos, 318 | F9: Centro | G9: (11) 4712-3121 | H9: 10 | I9: 10 | J9: =H9+I9 -> 20 | K9: 0.010416667 | L9: 0.010416667 | M9: =K9+L9 -> 0.020833333
A10: Cargill | B10: Hotel Araçari | C10: Araçariguama | D10: SP | E10: R. São João, 243 | F10: Centro | G10: (11) 4204-4133 | H10: 20 | I10: 20 | J10: =H10+I10 -> 40 | K10: 0.020833333 | L10: 0.020833333 | M10: =K10+L10 -> 0.041666667
A11: Gelita do Brasil | B11: Hotel Rafenna | C11: Mococa | D11: SP | E11: R. Estados Unidos, 620 | F11: Jardim Lavinia | G11: (19) 3665-4610 | H11: 5 | I11: 5 | J11: =H11+I11 -> 10 | K11: 0.0069444444 | L11: 0.0069444444 | M11: =K11+L11 -> 0.013888889
A12: Gelita do Brasil | B12: Maria de Lourdes de Souza Maldonado | C12: Mococa | D12: SP | E12: R. Costa Rica, 58 | F12: Jardim Lavinia | G12: (19) 98808-8234 | H12: 5 | I12: 5 | J12: =H12+I12 -> 10 | K12: 0.0069444444 | L12: 0.0069444444 | M12: =K12+L12 -> 0.013888889
A13: Lubrizol | B13: Nobile Inn Dutra Rio de Janeiro | C13: São João de Meriti | D13: RJ | E13: R. Sen. Nereu Ramos, 238 | F13: Jardim Meriti | G13: (21) 3512-1946 | H13: 8 | I13: 8 | J13: =H13+I13 -> 16 | K13: 0.010416667 | L13: 0.0069444444 | M13: =K13+L13 -> 0.017361111
A14: Lubrizol | B14: Hotel Avenida | C14: São João de Meriti | D14: RJ | E14: Rod. Pres. Dutra, 4013 | F14: Jardim Jose Bonifacio | G14: (21) 2756-1228 | H14: 7 | I14: 7 | J14: =H14+I14 -> 14 | K14: 0.010416667 | L14: 0.010416667 | M14: =K14+L14 -> 0.020833333
A15: Mercedes - Benz | B15: Pousada Aconchego | C15: Novo Horizonte | D15: MG | E15: R. Dr. Décio Guanabarino, 1 | F15: Juiz de Fora | G15: (32) 3233-1305 | H15: 30 | I15: 30 | J15: =H15+I15 -> 60 | K15: 0.017361111 | L15: 0.017361111 | M15: =K15+L15 -> 0.034722222
A16: Mosaic Co | B16: Havana Palace II | C16: Uberaba | D16: MG | E16: Av. Barão do Rio Branco, 338 | F16: São Benedito | G16: (34) 3316-9900 | H16: 30 | I16: 30 | J16: =H16+I16 -> 60 | K16: 0.027777778 | L16: 0.027777778 | M16: =K16+L16 -> 0.055555556
A17: Monin | B17: Hotel Itu Shopping | C17: Itu | D17: SP | E17: R. Santa Rita, 714 | F17: Centro | G17: (11) 98447-0347 | H17: 15 | I17: 15 | J17: =H17+I17 -> 30 | K17: 0.020833333 | L17: 0.020833333 | M17: =K17+L17 -> 0.041666667
A18: Pirelli | B18: Hotel Esplanada | C18: Campinas | D18: SP | E18: R. Onze de Agosto, 660 | F18: Centro | G18: (19) 99983-3215 | H18: 12 | I18: 13 | J18: =H18+I18 -> 25 | K18: 0.020833333 | L18: 0.020833333 | M18: =K18+L18 -> 0.041666667
... A27: Villares Metals | B27: Jaguary Hotel Sumaré | C27: Sumaré | D27: SP | E27: Rua Luiz José Duarte, 199 | F27: Centro | G27: (19) 3883-8400 | H27: 10 | I27: 10 | J27: =H27+I27 -> 20 | K27: 0.010416667 | L27: 0.010416667 | M27: =K27+L27 -> 0.020833333

Sheet Profissionais
A1: Alan Ferreira
A2: Alisson Oliveira
A3: Altino Geraldo
A4: Baltazar Costa
A5: Deivison Almeida
A6: Edson Gomes
A7: Felipe Orosco
A8: Felipe Paduano
A9: Felipe Sasso
A10: Gustavo Arruda
A11: João Vitor
A12: Jonathan Ferronato
... A24: Victor Fernando
